/g/data3/hh5/public/apps/miniconda3/envs/analysis3-22.10/lib/python3.9/site-packages/xarray/coding/times.py:699: SerializationWarning: Unable to decode time axis into full numpy.datetime64 objects, continuing using cftime.datetime objects instead, reason: dates out of range
  dtype = _decode_cf_datetime_dtype(data, units, calendar, self.use_cftime)
/g/data3/hh5/public/apps/miniconda3/envs/analysis3-22.10/lib/python3.9/site-packages/xarray/coding/times.py:699: SerializationWarning: Unable to decode time axis into full numpy.datetime64 objects, continuing using cftime.datetime objects instead, reason: dates out of range
  dtype = _decode_cf_datetime_dtype(data, units, calendar, self.use_cftime)
/g/data3/hh5/public/apps/miniconda3/envs/analysis3-22.10/lib/python3.9/site-packages/xarray/core/indexing.py:524: SerializationWarning: Unable to decode time axis into full numpy.datetime64 objects, continuing using cftime.datetime objects instead, reason: dates out of range
  return np.asarray(array[self.key], dtype=None)
/g/data/k10/cb4968/phd/cmip5_scripts/cmip5_metrics/funcs/vars/myPlots.py:17: RuntimeWarning: More than 20 figures have been opened. Figures created through the pyplot interface (`matplotlib.pyplot.figure`) are retained until explicitly closed and may consume too much memory. (To control this warning, see the rcParam `figure.max_open_warning`).
  f, ax = plt.subplots(subplot_kw=dict(projection=projection), figsize=(15, 5))
Traceback (most recent call last):
  File "/g/data/k10/cb4968/phd/cmip5_scripts/cmip5_metrics/funcs/vars/tasVars.py", line 163, in <module>
    plot_snapshot(ds_tas.tas.isel(time=0), 'Reds', 'surface temperature', model)
  File "/g/data3/hh5/public/apps/miniconda3/envs/analysis3-22.10/lib/python3.9/site-packages/xarray/core/dataarray.py", line 1398, in isel
    variable = self._variable.isel(indexers, missing_dims=missing_dims)
  File "/g/data3/hh5/public/apps/miniconda3/envs/analysis3-22.10/lib/python3.9/site-packages/xarray/core/variable.py", line 1322, in isel
    return self[key]
  File "/g/data3/hh5/public/apps/miniconda3/envs/analysis3-22.10/lib/python3.9/site-packages/xarray/core/variable.py", line 870, in __getitem__
    data = as_indexable(self._data)[indexer]
  File "/g/data3/hh5/public/apps/miniconda3/envs/analysis3-22.10/lib/python3.9/site-packages/xarray/core/indexing.py", line 1367, in __getitem__
    return self.array[key.tuple]
  File "/g/data3/hh5/public/apps/miniconda3/envs/analysis3-22.10/lib/python3.9/site-packages/dask/array/core.py", line 1962, in __getitem__
    index2 = normalize_index(index, self.shape)
  File "/g/data3/hh5/public/apps/miniconda3/envs/analysis3-22.10/lib/python3.9/site-packages/dask/array/slicing.py", line 917, in normalize_index
    check_index(axis, i, d)
  File "/g/data3/hh5/public/apps/miniconda3/envs/analysis3-22.10/lib/python3.9/site-packages/dask/array/slicing.py", line 989, in check_index
    raise IndexError(
IndexError: Index 0 is out of bounds for axis 0 with size 0
